Workbook

Sheet BDTRAFOS

Sheet HI
E2: 5 | F2: 2 | G2: 5 | H2: 4 | I2: 2 | J2: 1 | K2: 1
B3: SERIE | C3: FECHA | D3: HI | E3: =+HIDGA!D3 -> HIDGA | F3: =+HIACE!D3 -> HIACE | G3: =+HIAIS!D3 -> HIAIS | H3: =+HIARR!D3 -> HIARR | I3: =+HINUC!D3 -> HINUC | J3: =+HIOLTC!D3 -> HIOLTC | K3: =+HIBUS!D3 -> HIBUS
B4: S1 | C4: =+TODAY() -> 45917 | D4: =+(E4*$E$2+F4*$F$2+G4*$G$2+H4*$H$2+I4*$I$2+J4*$J$2+K4*$K$2)/SUM($E$2:$K$2) -> 12.694424 | E4: =+VLOOKUP($B4,HIDGA!$B$4:$D$13,3,FALSE) -> 4.25 | F4: =+VLOOKUP($B4,HIACE!$B$4:$D$13,3,FALSE) -> 13.227273 | G4: =+VLOOKUP($B4,HIAIS!$B$4:$D$13,3,FALSE) -> 5.6153846 | H4: =+VLOOKUP($B4,HIARR!$B$4:$D$13,3,FALSE) -> 30.769231 | I4: =+VLOOKUP($B4,HINUC!$B$4:$D$13,3,FALSE) -> 1.6363636 | J4: =+VLOOKUP($B4,HIOLTC!$B$4:$D$13,3,FALSE) -> 46.875 | K4: =+VLOOKUP($B4,HIBUS!$B$4:$D$13,3,FALSE) -> 4.8823529
B5: S2 | C5: =+TODAY() -> 45917 | D5: =+(E5*$E$2+F5*$F$2+G5*$G$2+H5*$H$2+I5*$I$2+J5*$J$2+K5*$K$2)/SUM($E$2:$K$2) -> 5.5002288 | E5: =+VLOOKUP($B5,HIDGA!$B$4:$D$13,3,FALSE) -> 4.7 | F5: =+VLOOKUP($B5,HIACE!$B$4:$D$13,3,FALSE) -> 8.2272727 | G5: =+VLOOKUP($B5,HIAIS!$B$4:$D$13,3,FALSE) -> 7.5384615 | H5: =+VLOOKUP($B5,HIARR!$B$4:$D$13,3,FALSE) -> 1.5384615 | I5: =+VLOOKUP($B5,HINUC!$B$4:$D$13,3,FALSE) -> 7.0909091 | J5: =+VLOOKUP($B5,HIOLTC!$B$4:$D$13,3,FALSE) -> 9.375 | K5: =+VLOOKUP($B5,HIBUS!$B$4:$D$13,3,FALSE) -> 2.6470588
B6: S3 | C6: =+TODAY() -> 45917 | D6: =+(E6*$E$2+F6*$F$2+G6*$G$2+H6*$H$2+I6*$I$2+J6*$J$2+K6*$K$2)/SUM($E$2:$K$2) -> 3.9047743 | E6: =+VLOOKUP($B6,HIDGA!$B$4:$D$13,3,FALSE) -> 2.8 | F6: =+VLOOKUP($B6,HIACE!$B$4:$D$13,3,FALSE) -> 5.0454545 | G6: =+VLOOKUP($B6,HIAIS!$B$4:$D$13,3,FALSE) -> 1.8461538 | H6: =+VLOOKUP($B6,HIARR!$B$4:$D$13,3,FALSE) -> 6.1538462 | I6: =+VLOOKUP($B6,HINUC!$B$4:$D$13,3,FALSE) -> 6.8181818 | J6: =+VLOOKUP($B6,HIOLTC!$B$4:$D$13,3,FALSE) -> 1.875 | K6: =+VLOOKUP($B6,HIBUS!$B$4:$D$13,3,FALSE) -> 4.6470588
B7: S4 | C7: =+TODAY() -> 45917 | D7: =+(E7*$E$2+F7*$F$2+G7*$G$2+H7*$H$2+I7*$I$2+J7*$J$2+K7*$K$2)/SUM($E$2:$K$2) -> 5.0459559 | E7: =+VLOOKUP($B7,HIDGA!$B$4:$D$13,3,FALSE) -> 2.95 | F7: =+VLOOKUP($B7,HIACE!$B$4:$D$13,3,FALSE) -> 2.9545455 | G7: =+VLOOKUP($B7,HIAIS!$B$4:$D$13,3,FALSE) -> 1.7692308 | H7: =+VLOOKUP($B7,HIARR!$B$4:$D$13,3,FALSE) -> 1.5384615 | I7: =+VLOOKUP($B7,HINUC!$B$4:$D$13,3,FALSE) -> 27.545455 | J7: =+VLOOKUP($B7,HIOLTC!$B$4:$D$13,3,FALSE) -> 1.875 | K7: =+VLOOKUP($B7,HIBUS!$B$4:$D$13,3,FALSE) -> 8.2941176
B8: S5 | C8: =+TODAY() -> 45917 | D8: =+(E8*$E$2+F8*$F$2+G8*$G$2+H8*$H$2+I8*$I$2+J8*$J$2+K8*$K$2)/SUM($E$2:$K$2) -> 4.0475859 | E8: =+VLOOKUP($B8,HIDGA!$B$4:$D$13,3,FALSE) -> 5 | F8: =+VLOOKUP($B8,HIACE!$B$4:$D$13,3,FALSE) -> 3.2272727 | G8: =+VLOOKUP($B8,HIAIS!$B$4:$D$13,3,FALSE) -> 4.9230769 | H8: =+VLOOKUP($B8,HIARR!$B$4:$D$13,3,FALSE) -> 1.5384615 | I8: =+VLOOKUP($B8,HINUC!$B$4:$D$13,3,FALSE) -> 3 | J8: =+VLOOKUP($B8,HIOLTC!$B$4:$D$13,3,FALSE) -> 9.375 | K8: =+VLOOKUP($B8,HIBUS!$B$4:$D$13,3,FALSE) -> 3.3529412
B9: S6 | C9: =+TODAY() -> 45917 | D9: =+(E9*$E$2+F9*$F$2+G9*$G$2+H9*$H$2+I9*$I$2+J9*$J$2+K9*$K$2)/SUM($E$2:$K$2) -> 9.3912202 | E9: =+VLOOKUP($B9,HIDGA!$B$4:$D$13,3,FALSE) -> 3.5 | F9: =+VLOOKUP($B9,HIACE!$B$4:$D$13,3,FALSE) -> 7.9545455 | G9: =+VLOOKUP($B9,HIAIS!$B$4:$D$13,3,FALSE) -> 3.0769231 | H9: =+VLOOKUP($B9,HIARR!$B$4:$D$13,3,FALSE) -> 29.230769 | I9: =+VLOOKUP($B9,HINUC!$B$4:$D$13,3,FALSE) -> 5.4545455 | J9: =+VLOOKUP($B9,HIOLTC!$B$4:$D$13,3,FALSE) -> 9.375 | K9: =+VLOOKUP($B9,HIBUS!$B$4:$D$13,3,FALSE) -> 1.8235294
B10: S7 | C10: =+TODAY() -> 45917 | D10: =+(E10*$E$2+F10*$F$2+G10*$G$2+H10*$H$2+I10*$I$2+J10*$J$2+K10*$K$2)/SUM($E$2:$K$2) -> 8.1283551 | E10: =+VLOOKUP($B10,HIDGA!$B$4:$D$13,3,FALSE) -> 3.9 | F10: =+VLOOKUP($B10,HIACE!$B$4:$D$13,3,FALSE) -> 11.227273 | G10: =+VLOOKUP($B10,HIAIS!$B$4:$D$13,3,FALSE) -> 10.923077 | H10: =+VLOOKUP($B10,HIARR!$B$4:$D$13,3,FALSE) -> 7.6923077 | I10: =+VLOOKUP($B10,HINUC!$B$4:$D$13,3,FALSE) -> 15 | J10: =+VLOOKUP($B10,HIOLTC!$B$4:$D$13,3,FALSE) -> 1.875 | K10: =+VLOOKUP($B10,HIBUS!$B$4:$D$13,3,FALSE) -> 3.3529412
B11: S8 | C11: =+TODAY() -> 45917 | D11: =+(E11*$E$2+F11*$F$2+G11*$G$2+H11*$H$2+I11*$I$2+J11*$J$2+K11*$K$2)/SUM($E$2:$K$2) -> 6.1935135 | E11: =+VLOOKUP($B11,HIDGA!$B$4:$D$13,3,FALSE) -> 9.5 | F11: =+VLOOKUP($B11,HIACE!$B$4:$D$13,3,FALSE) -> 4.3181818 | G11: =+VLOOKUP($B11,HIAIS!$B$4:$D$13,3,FALSE) -> 2.4615385 | H11: =+VLOOKUP($B11,HIARR!$B$4:$D$13,3,FALSE) -> 6.1538462 | I11: =+VLOOKUP($B11,HINUC!$B$4:$D$13,3,FALSE) -> 13.909091 | J11: =+VLOOKUP($B11,HIOLTC!$B$4:$D$13,3,FALSE) -> 1.875 | K11: =+VLOOKUP($B11,HIBUS!$B$4:$D$13,3,FALSE) -> 1.1176471
B12: S9 | C12: =+TODAY() -> 45917 | D12: =+(E12*$E$2+F12*$F$2+G12*$G$2+H12*$H$2+I12*$I$2+J12*$J$2+K12*$K$2)/SUM($E$2:$K$2) -> 9.9988816 | E12: =+VLOOKUP($B12,HIDGA!$B$4:$D$13,3,FALSE) -> 6 | F12: =+VLOOKUP($B12,HIACE!$B$4:$D$13,3,FALSE) -> 2.7727273 | G12: =+VLOOKUP($B12,HIAIS!$B$4:$D$13,3,FALSE) -> 2.6923077 | H12: =+VLOOKUP($B12,HIARR!$B$4:$D$13,3,FALSE) -> 30.769231 | I12: =+VLOOKUP($B12,HINUC!$B$4:$D$13,3,FALSE) -> 6.8181818 | J12: =+VLOOKUP($B12,HIOLTC!$B$4:$D$13,3,FALSE) -> 9.375 | K12: =+VLOOKUP($B12,HIBUS!$B$4:$D$13,3,FALSE) -> 4.8823529
B13: S10 | C13: =+TODAY() -> 45917 | D13: =+(E13*$E$2+F13*$F$2+G13*$G$2+H13*$H$2+I13*$I$2+J13*$J$2+K13*$K$2)/SUM($E$2:$K$2) -> 3.7576332 | E13: =+VLOOKUP($B13,HIDGA!$B$4:$D$13,3,FALSE) -> 6.2 | F13: =+VLOOKUP($B13,HIACE!$B$4:$D$13,3,FALSE) -> 2.8636364 | G13: =+VLOOKUP($B13,HIAIS!$B$4:$D$13,3,FALSE) -> 2.2307692 | H13: =+VLOOKUP($B13,HIARR!$B$4:$D$13,3,FALSE) -> 2.3076923 | I13: =+VLOOKUP($B13,HINUC!$B$4:$D$13,3,FALSE) -> 6.8181818 | J13: =+VLOOKUP($B13,HIOLTC!$B$4:$D$13,3,FALSE) -> 1.875 | K13: =+VLOOKUP($B13,HIBUS!$B$4:$D$13,3,FALSE) -> 2.5294118
B14: S1 | C14: =+TODAY()-1 -> 45916 | D14: =+RANDBETWEEN(1,10) -> 1
B15: S2 | C15: =+TODAY()-1 -> 45916 | D15: =+RANDBETWEEN(1,10) -> 2
B16: S3 | C16: =+TODAY()-1 -> 45916 | D16: =+RANDBETWEEN(1,10) -> 7
B17: S4 | C17: =+TODAY()-1 -> 45916 | D17: =+RANDBETWEEN(1,10) -> 1
B18: S5 | C18: =+TODAY()-1 -> 45916 | D18: =+RANDBETWEEN(1,10) -> 2
B19: S6 | C19: =+TODAY()-1 -> 45916 | D19: =+RANDBETWEEN(1,10) -> 7
B20: S7 | C20: =+TODAY()-1 -> 45916 | D20: =+RANDBETWEEN(1,10) -> 5
B21: S8 | C21: =+TODAY()-1 -> 45916 | D21: =+RANDBETWEEN(1,10) -> 2
B22: S9 | C22: =+TODAY()-1 -> 45916 | D22: =+RANDBETWEEN(1,10) -> 3
B23: S10 | C23: =+TODAY()-1 -> 45916 | D23: =+RANDBETWEEN(1,10) -> 2
B24: S1 | C24: =+TODAY()-2 -> 45915
B25: S2 | C25: =+TODAY()-2 -> 45915
B26: S3 | C26: =+TODAY()-2 -> 45915
B27: S4 | C27: =+TODAY()-2 -> 45915
B28: S5 | C28: =+TODAY()-2 -> 45915
B29: S6 | C29: =+TODAY()-2 -> 45915
B30: S7 | C30: =+TODAY()-2 -> 45915
B31: S8 | C31: =+TODAY()-2 -> 45915
B32: S9 | C32: =+TODAY()-2 -> 45915
B33: S10 | C33: =+TODAY()-2 -> 45915
B34: S1 | C34: =+TODAY()-2 -> 45915
B35: S2 | C35: =+TODAY()-3 -> 45914
B36: S3 | C36: =+TODAY()-3 -> 45914
B37: S4 | C37: =+TODAY()-3 -> 45914
B38: S5 | C38: =+TODAY()-3 -> 45914
B39: S6 | C39: =+TODAY()-3 -> 45914
B40: S7 | C40: =+TODAY()-3 -> 45914
B41: S8 | C41: =+TODAY()-3 -> 45914
...

Sheet HIDGA
D2: 5 | E2: 5 | F2: 2 | G2: 3 | H2: 4 | I2: 3 | J2: 2 | K2: 1
B3: SERIE | C3: FECHA | D3: HIDGA | E3: P_C2H2 | F3: P_H2 | G3: P_CH4 | H3: P_C2H4 | I3: P_C2H6 | J3: P_CO | K3: P_CO2
B4: S1 | C4: =+RANDBETWEEN(40000,45000) -> 44833 | D4: =+(E4*$E$2*F4*$F$2+G4*$G$2+H4*$H$2+I4*$I$2+J4*$J$2+K4*$K$2)/SUM($E$2:$K$2) -> 4.25 | E4: =+RANDBETWEEN(1,5) -> 5 | F4: =+RANDBETWEEN(1,5) -> 1 | G4: =+RANDBETWEEN(1,5) -> 2 | H4: =+RANDBETWEEN(1,5) -> 5 | I4: =+RANDBETWEEN(1,5) -> 2 | J4: =+RANDBETWEEN(1,5) -> 1 | K4: =+RANDBETWEEN(1,5) -> 1
B5: S2 | C5: =+RANDBETWEEN(40000,45000) -> 41329 | D5: =+(E5*$E$2*F5*$F$2+G5*$G$2+H5*$H$2+I5*$I$2+J5*$J$2+K5*$K$2)/SUM($E$2:$K$2) -> 4.7 | E5: =+RANDBETWEEN(1,5) -> 5 | F5: =+RANDBETWEEN(1,5) -> 1 | G5: =+RANDBETWEEN(1,5) -> 5 | H5: =+RANDBETWEEN(1,5) -> 3 | I5: =+RANDBETWEEN(1,5) -> 3 | J5: =+RANDBETWEEN(1,5) -> 2 | K5: =+RANDBETWEEN(1,5) -> 4
B6: S3 | C6: =+RANDBETWEEN(40000,45000) -> 41484 | D6: =+(E6*$E$2*F6*$F$2+G6*$G$2+H6*$H$2+I6*$I$2+J6*$J$2+K6*$K$2)/SUM($E$2:$K$2) -> 2.8 | E6: =+RANDBETWEEN(1,5) -> 2 | F6: =+RANDBETWEEN(1,5) -> 1 | G6: =+RANDBETWEEN(1,5) -> 2 | H6: =+RANDBETWEEN(1,5) -> 2 | I6: =+RANDBETWEEN(1,5) -> 4 | J6: =+RANDBETWEEN(1,5) -> 4 | K6: =+RANDBETWEEN(1,5) -> 2
B7: S4 | C7: =+RANDBETWEEN(40000,45000) -> 43315 | D7: =+(E7*$E$2*F7*$F$2+G7*$G$2+H7*$H$2+I7*$I$2+J7*$J$2+K7*$K$2)/SUM($E$2:$K$2) -> 2.95 | E7: =+RANDBETWEEN(1,5) -> 1 | F7: =+RANDBETWEEN(1,5) -> 1 | G7: =+RANDBETWEEN(1,5) -> 4 | H7: =+RANDBETWEEN(1,5) -> 5 | I7: =+RANDBETWEEN(1,5) -> 2 | J7: =+RANDBETWEEN(1,5) -> 4 | K7: =+RANDBETWEEN(1,5) -> 3
B8: S5 | C8: =+RANDBETWEEN(40000,45000) -> 41581 | D8: =+(E8*$E$2*F8*$F$2+G8*$G$2+H8*$H$2+I8*$I$2+J8*$J$2+K8*$K$2)/SUM($E$2:$K$2) -> 5 | E8: =+RANDBETWEEN(1,5) -> 2 | F8: =+RANDBETWEEN(1,5) -> 3 | G8: =+RANDBETWEEN(1,5) -> 5 | H8: =+RANDBETWEEN(1,5) -> 4 | I8: =+RANDBETWEEN(1,5) -> 1 | J8: =+RANDBETWEEN(1,5) -> 1 | K8: =+RANDBETWEEN(1,5) -> 4
B9: S6 | C9: =+RANDBETWEEN(40000,45000) -> 42506 | D9: =+(E9*$E$2*F9*$F$2+G9*$G$2+H9*$H$2+I9*$I$2+J9*$J$2+K9*$K$2)/SUM($E$2:$K$2) -> 3.5 | E9: =+RANDBETWEEN(1,5) -> 1 | F9: =+RANDBETWEEN(1,5) -> 1 | G9: =+RANDBETWEEN(1,5) -> 5 | H9: =+RANDBETWEEN(1,5) -> 5 | I9: =+RANDBETWEEN(1,5) -> 5 | J9: =+RANDBETWEEN(1,5) -> 3 | K9: =+RANDBETWEEN(1,5) -> 4
B10: S7 | C10: =+RANDBETWEEN(40000,45000) -> 42801 | D10: =+(E10*$E$2*F10*$F$2+G10*$G$2+H10*$H$2+I10*$I$2+J10*$J$2+K10*$K$2)/SUM($E$2:$K$2) -> 3.9 | E10: =+RANDBETWEEN(1,5) -> 4 | F10: =+RANDBETWEEN(1,5) -> 1 | G10: =+RANDBETWEEN(1,5) -> 3 | H10: =+RANDBETWEEN(1,5) -> 2 | I10: =+RANDBETWEEN(1,5) -> 2 | J10: =+RANDBETWEEN(1,5) -> 5 | K10: =+RANDBETWEEN(1,5) -> 5
B11: S8 | C11: =+RANDBETWEEN(40000,45000) -> 44784 | D11: =+(E11*$E$2*F11*$F$2+G11*$G$2+H11*$H$2+I11*$I$2+J11*$J$2+K11*$K$2)/SUM($E$2:$K$2) -> 9.5 | E11: =+RANDBETWEEN(1,5) -> 4 | F11: =+RANDBETWEEN(1,5) -> 4 | G11: =+RANDBETWEEN(1,5) -> 4 | H11: =+RANDBETWEEN(1,5) -> 2 | I11: =+RANDBETWEEN(1,5) -> 1 | J11: =+RANDBETWEEN(1,5) -> 2 | K11: =+RANDBETWEEN(1,5) -> 3
B12: S9 | C12: =+RANDBETWEEN(40000,45000) -> 42819 | D12: =+(E12*$E$2*F12*$F$2+G12*$G$2+H12*$H$2+I12*$I$2+J12*$J$2+K12*$K$2)/SUM($E$2:$K$2) -> 6 | E12: =+RANDBETWEEN(1,5) -> 3 | F12: =+RANDBETWEEN(1,5) -> 2 | G12: =+RANDBETWEEN(1,5) -> 5 | H12: =+RANDBETWEEN(1,5) -> 5 | I12: =+RANDBETWEEN(1,5) -> 4 | J12: =+RANDBETWEEN(1,5) -> 4 | K12: =+RANDBETWEEN(1,5) -> 5
B13: S10 | C13: =+RANDBETWEEN(40000,45000) -> 40031 | D13: =+(E13*$E$2*F13*$F$2+G13*$G$2+H13*$H$2+I13*$I$2+J13*$J$2+K13*$K$2)/SUM($E$2:$K$2) -> 6.2 | E13: =+RANDBETWEEN(1,5) -> 2 | F13: =+RANDBETWEEN(1,5) -> 4 | G13: =+RANDBETWEEN(1,5) -> 1 | H13: =+RANDBETWEEN(1,5) -> 5 | I13: =+RANDBETWEEN(1,5) -> 5 | J13: =+RANDBETWEEN(1,5) -> 1 | K13: =+RANDBETWEEN(1,5) -> 4
B14: S11
B15: S12
B16: S13 | C16: S1 | E16: HIDGA | F16: HIACE | G16: HIAIS
B17: S14 | E17: HIARR | F17: HINUC | G17: HIOLTC
B18: S15 | E18: HIBUS
B19: S16
B20: S17
B21: S18
B22: S19
B23: S20
B24: S21
B25: S22
B26: S23
B27: S24
B28: S25
B29: S26
B30: S27
... B133: S130

Sheet HIACE
D2: 2 | E2: 3 | F2: 3 | G2: 4 | H2: 2 | I2: 3 | J2: 1 | K2: 5 | L2: 1
B3: SERIE | C3: FECHA | D3: HIACE | E3: P_FP25 | F3: P_FP100 | G3: P_HU | H3: P_AC | I3: P_TIF | J3: P_CO | K3: P_RD | L3: P_IO
B4: S1 | C4: =+RANDBETWEEN(40000,45000) -> 41786 | D4: =+(E4*$E$2*F4*$F$2+G4*$G$2+H4*$H$2+I4*$I$2+J4*$J$2+K4*$K$2+L4*$L$2)/SUM($E$2:$L$2) -> 13.227273 | E4: =2*RANDBETWEEN(1,3)-1 -> 5 | F4: =2*RANDBETWEEN(1,3)-1 -> 5 | G4: =2*RANDBETWEEN(1,3)-1 -> 3 | H4: =2*RANDBETWEEN(1,3)-1 -> 5 | I4: =2*RANDBETWEEN(1,3)-1 -> 5 | J4: =2*RANDBETWEEN(1,3)-1 -> 1 | K4: =2*RANDBETWEEN(1,3)-1 -> 5 | L4: =2*RANDBETWEEN(1,3)-1 -> 3
B5: S2 | C5: =+RANDBETWEEN(40000,45000) -> 40981 | D5: =+(E5*$E$2*F5*$F$2+G5*$G$2+H5*$H$2+I5*$I$2+J5*$J$2+K5*$K$2+L5*$L$2)/SUM($E$2:$L$2) -> 8.2272727 | E5: =2*RANDBETWEEN(1,3)-1 -> 5 | F5: =2*RANDBETWEEN(1,3)-1 -> 3 | G5: =2*RANDBETWEEN(1,3)-1 -> 3 | H5: =2*RANDBETWEEN(1,3)-1 -> 5 | I5: =2*RANDBETWEEN(1,3)-1 -> 5 | J5: =2*RANDBETWEEN(1,3)-1 -> 3 | K5: =2*RANDBETWEEN(1,3)-1 -> 1 | L5: =2*RANDBETWEEN(1,3)-1 -> 1
B6: S3 | C6: =+RANDBETWEEN(40000,45000) -> 43122 | D6: =+(E6*$E$2*F6*$F$2+G6*$G$2+H6*$H$2+I6*$I$2+J6*$J$2+K6*$K$2+L6*$L$2)/SUM($E$2:$L$2) -> 5.0454545 | E6: =2*RANDBETWEEN(1,3)-1 -> 1 | F6: =2*RANDBETWEEN(1,3)-1 -> 5 | G6: =2*RANDBETWEEN(1,3)-1 -> 5 | H6: =2*RANDBETWEEN(1,3)-1 -> 3 | I6: =2*RANDBETWEEN(1,3)-1 -> 5 | J6: =2*RANDBETWEEN(1,3)-1 -> 5 | K6: =2*RANDBETWEEN(1,3)-1 -> 3 | L6: =2*RANDBETWEEN(1,3)-1 -> 5
B7: S4 | C7: =+RANDBETWEEN(40000,45000) -> 43188 | D7: =+(E7*$E$2*F7*$F$2+G7*$G$2+H7*$H$2+I7*$I$2+J7*$J$2+K7*$K$2+L7*$L$2)/SUM($E$2:$L$2) -> 2.9545455 | E7: =2*RANDBETWEEN(1,3)-1 -> 3 | F7: =2*RANDBETWEEN(1,3)-1 -> 1 | G7: =2*RANDBETWEEN(1,3)-1 -> 3 | H7: =2*RANDBETWEEN(1,3)-1 -> 3 | I7: =2*RANDBETWEEN(1,3)-1 -> 3 | J7: =2*RANDBETWEEN(1,3)-1 -> 5 | K7: =2*RANDBETWEEN(1,3)-1 -> 1 | L7: =2*RANDBETWEEN(1,3)-1 -> 1
B8: S5 | C8: =+RANDBETWEEN(40000,45000) -> 44056 | D8: =+(E8*$E$2*F8*$F$2+G8*$G$2+H8*$H$2+I8*$I$2+J8*$J$2+K8*$K$2+L8*$L$2)/SUM($E$2:$L$2) -> 3.2272727 | E8: =2*RANDBETWEEN(1,3)-1 -> 1 | F8: =2*RANDBETWEEN(1,3)-1 -> 5 | G8: =2*RANDBETWEEN(1,3)-1 -> 3 | H8: =2*RANDBETWEEN(1,3)-1 -> 1 | I8: =2*RANDBETWEEN(1,3)-1 -> 1 | J8: =2*RANDBETWEEN(1,3)-1 -> 3 | K8: =2*RANDBETWEEN(1,3)-1 -> 1 | L8: =2*RANDBETWEEN(1,3)-1 -> 1
B9: S6 | C9: =+RANDBETWEEN(40000,45000) -> 41508 | D9: =+(E9*$E$2*F9*$F$2+G9*$G$2+H9*$H$2+I9*$I$2+J9*$J$2+K9*$K$2+L9*$L$2)/SUM($E$2:$L$2) -> 7.9545455 | E9: =2*RANDBETWEEN(1,3)-1 -> 3 | F9: =2*RANDBETWEEN(1,3)-1 -> 5 | G9: =2*RANDBETWEEN(1,3)-1 -> 1 | H9: =2*RANDBETWEEN(1,3)-1 -> 5 | I9: =2*RANDBETWEEN(1,3)-1 -> 3 | J9: =2*RANDBETWEEN(1,3)-1 -> 1 | K9: =2*RANDBETWEEN(1,3)-1 -> 3 | L9: =2*RANDBETWEEN(1,3)-1 -> 1
B10: S7 | C10: =+RANDBETWEEN(40000,45000) -> 43401 | D10: =+(E10*$E$2*F10*$F$2+G10*$G$2+H10*$H$2+I10*$I$2+J10*$J$2+K10*$K$2+L10*$L$2)/SUM($E$2:$L$2) -> 11.227273 | E10: =2*RANDBETWEEN(1,3)-1 -> 5 | F10: =2*RANDBETWEEN(1,3)-1 -> 5 | G10: =2*RANDBETWEEN(1,3)-1 -> 1 | H10: =2*RANDBETWEEN(1,3)-1 -> 1 | I10: =2*RANDBETWEEN(1,3)-1 -> 1 | J10: =2*RANDBETWEEN(1,3)-1 -> 3 | K10: =2*RANDBETWEEN(1,3)-1 -> 1 | L10: =2*RANDBETWEEN(1,3)-1 -> 5
B11: S8 | C11: =+RANDBETWEEN(40000,45000) -> 41950 | D11: =+(E11*$E$2*F11*$F$2+G11*$G$2+H11*$H$2+I11*$I$2+J11*$J$2+K11*$K$2+L11*$L$2)/SUM($E$2:$L$2) -> 4.3181818 | E11: =2*RANDBETWEEN(1,3)-1 -> 1 | F11: =2*RANDBETWEEN(1,3)-1 -> 5 | G11: =2*RANDBETWEEN(1,3)-1 -> 1 | H11: =2*RANDBETWEEN(1,3)-1 -> 5 | I11: =2*RANDBETWEEN(1,3)-1 -> 3 | J11: =2*RANDBETWEEN(1,3)-1 -> 1 | K11: =2*RANDBETWEEN(1,3)-1 -> 5 | L11: =2*RANDBETWEEN(1,3)-1 -> 1
B12: S9 | C12: =+RANDBETWEEN(40000,45000) -> 42261 | D12: =+(E12*$E$2*F12*$F$2+G12*$G$2+H12*$H$2+I12*$I$2+J12*$J$2+K12*$K$2+L12*$L$2)/SUM($E$2:$L$2) -> 2.7727273 | E12: =2*RANDBETWEEN(1,3)-1 -> 1 | F12: =2*RANDBETWEEN(1,3)-1 -> 1 | G12: =2*RANDBETWEEN(1,3)-1 -> 5 | H12: =2*RANDBETWEEN(1,3)-1 -> 1 | I12: =2*RANDBETWEEN(1,3)-1 -> 3 | J12: =2*RANDBETWEEN(1,3)-1 -> 1 | K12: =2*RANDBETWEEN(1,3)-1 -> 3 | L12: =2*RANDBETWEEN(1,3)-1 -> 5
B13: S10 | C13: =+RANDBETWEEN(40000,45000) -> 42742 | D13: =+(E13*$E$2*F13*$F$2+G13*$G$2+H13*$H$2+I13*$I$2+J13*$J$2+K13*$K$2+L13*$L$2)/SUM($E$2:$L$2) -> 2.8636364 | E13: =2*RANDBETWEEN(1,3)-1 -> 3 | F13: =2*RANDBETWEEN(1,3)-1 -> 1 | G13: =2*RANDBETWEEN(1,3)-1 -> 3 | H13: =2*RANDBETWEEN(1,3)-1 -> 3 | I13: =2*RANDBETWEEN(1,3)-1 -> 3 | J13: =2*RANDBETWEEN(1,3)-1 -> 3 | K13: =2*RANDBETWEEN(1,3)-1 -> 1 | L13: =2*RANDBETWEEN(1,3)-1 -> 1

Sheet HIAIS
D2: 5 | E2: 1 | F2: 5 | G2: 2 | H2: 2 | I2: 3
B3: SERIE | C3: FECHA | D3: HIAIS | E3: P_VUT | F3: P_ECC | G3: P_FUR | H3: P_FDP | I3: P_CD
B4: S1 | C4: =+RANDBETWEEN(40000,45000) -> 43418 | D4: =+(E4*$E$2*F4*$F$2+G4*$G$2+H4*$H$2+I4*$I$2)/SUM($E$2:$I$2) -> 5.6153846 | E4: =+RANDBETWEEN(1,5) -> 4 | F4: =+RANDBETWEEN(1,5) -> 3 | G4: =+RANDBETWEEN(1,5) -> 2 | H4: =2*RANDBETWEEN(1,3)-1 -> 3 | I4: =2*RANDBETWEEN(1,3)-1 -> 1
B5: S2 | C5: =+RANDBETWEEN(40000,45000) -> 44890 | D5: =+(E5*$E$2*F5*$F$2+G5*$G$2+H5*$H$2+I5*$I$2)/SUM($E$2:$I$2) -> 7.5384615 | E5: =+RANDBETWEEN(1,5) -> 5 | F5: =+RANDBETWEEN(1,5) -> 3 | G5: =+RANDBETWEEN(1,5) -> 5 | H5: =2*RANDBETWEEN(1,3)-1 -> 5 | I5: =2*RANDBETWEEN(1,3)-1 -> 1
B6: S3 | C6: =+RANDBETWEEN(40000,45000) -> 43020 | D6: =+(E6*$E$2*F6*$F$2+G6*$G$2+H6*$H$2+I6*$I$2)/SUM($E$2:$I$2) -> 1.8461538 | E6: =+RANDBETWEEN(1,5) -> 1 | F6: =+RANDBETWEEN(1,5) -> 1 | G6: =+RANDBETWEEN(1,5) -> 5 | H6: =2*RANDBETWEEN(1,3)-1 -> 3 | I6: =2*RANDBETWEEN(1,3)-1 -> 1
B7: S4 | C7: =+RANDBETWEEN(40000,45000) -> 40331 | D7: =+(E7*$E$2*F7*$F$2+G7*$G$2+H7*$H$2+I7*$I$2)/SUM($E$2:$I$2) -> 1.7692308 | E7: =+RANDBETWEEN(1,5) -> 1 | F7: =+RANDBETWEEN(1,5) -> 2 | G7: =+RANDBETWEEN(1,5) -> 4 | H7: =2*RANDBETWEEN(1,3)-1 -> 1 | I7: =2*RANDBETWEEN(1,3)-1 -> 1
B8: S5 | C8: =+RANDBETWEEN(40000,45000) -> 43822 | D8: =+(E8*$E$2*F8*$F$2+G8*$G$2+H8*$H$2+I8*$I$2)/SUM($E$2:$I$2) -> 4.9230769 | E8: =+RANDBETWEEN(1,5) -> 3 | F8: =+RANDBETWEEN(1,5) -> 3 | G8: =+RANDBETWEEN(1,5) -> 5 | H8: =2*RANDBETWEEN(1,3)-1 -> 3 | I8: =2*RANDBETWEEN(1,3)-1 -> 1
B9: S6 | C9: =+RANDBETWEEN(40000,45000) -> 41343 | D9: =+(E9*$E$2*F9*$F$2+G9*$G$2+H9*$H$2+I9*$I$2)/SUM($E$2:$I$2) -> 3.0769231 | E9: =+RANDBETWEEN(1,5) -> 1 | F9: =+RANDBETWEEN(1,5) -> 5 | G9: =+RANDBETWEEN(1,5) -> 2 | H9: =2*RANDBETWEEN(1,3)-1 -> 1 | I9: =2*RANDBETWEEN(1,3)-1 -> 3
B10: S7 | C10: =+RANDBETWEEN(40000,45000) -> 40714 | D10: =+(E10*$E$2*F10*$F$2+G10*$G$2+H10*$H$2+I10*$I$2)/SUM($E$2:$I$2) -> 10.923077 | E10: =+RANDBETWEEN(1,5) -> 5 | F10: =+RANDBETWEEN(1,5) -> 5 | G10: =+RANDBETWEEN(1,5) -> 3 | H10: =2*RANDBETWEEN(1,3)-1 -> 1 | I10: =2*RANDBETWEEN(1,3)-1 -> 3
B11: S8 | C11: =+RANDBETWEEN(40000,45000) -> 42235 | D11: =+(E11*$E$2*F11*$F$2+G11*$G$2+H11*$H$2+I11*$I$2)/SUM($E$2:$I$2) -> 2.4615385 | E11: =+RANDBETWEEN(1,5) -> 1 | F11: =+RANDBETWEEN(1,5) -> 3 | G11: =+RANDBETWEEN(1,5) -> 3 | H11: =2*RANDBETWEEN(1,3)-1 -> 1 | I11: =2*RANDBETWEEN(1,3)-1 -> 3
B12: S9 | C12: =+RANDBETWEEN(40000,45000) -> 40789 | D12: =+(E12*$E$2*F12*$F$2+G12*$G$2+H12*$H$2+I12*$I$2)/SUM($E$2:$I$2) -> 2.6923077 | E12: =+RANDBETWEEN(1,5) -> 1 | F12: =+RANDBETWEEN(1,5) -> 4 | G12: =+RANDBETWEEN(1,5) -> 3 | H12: =2*RANDBETWEEN(1,3)-1 -> 3 | I12: =2*RANDBETWEEN(1,3)-1 -> 1
B13: S10 | C13: =+RANDBETWEEN(40000,45000) -> 43337 | D13: =+(E13*$E$2*F13*$F$2+G13*$G$2+H13*$H$2+I13*$I$2)/SUM($E$2:$I$2) -> 2.2307692 | E13: =+RANDBETWEEN(1,5) -> 1 | F13: =+RANDBETWEEN(1,5) -> 2 | G13: =+RANDBETWEEN(1,5) -> 2 | H13: =2*RANDBETWEEN(1,3)-1 -> 3 | I13: =2*RANDBETWEEN(1,3)-1 -> 3

Sheet HIARR
D2: 4 | E2: 3 | F2: 5 | G2: 5
B3: SERIE | C3: FECHA | D3: HIARR | E3: P_ROHM | F3: P_RTRA | G3: P_ZCC
B4: S1 | C4: =+RANDBETWEEN(40000,45000) -> 44475 | D4: =+(E4*$E$2*F4*$F$2+G4*$G$2)/SUM($E$2:$G$2) -> 30.769231 | E4: =+POWER(5,RANDBETWEEN(1,2)-1) -> 5 | F4: =+POWER(5,RANDBETWEEN(1,2)-1) -> 5 | G4: =2*RANDBETWEEN(1,3)-1 -> 5
B5: S2 | C5: =+RANDBETWEEN(40000,45000) -> 41705 | D5: =+(E5*$E$2*F5*$F$2+G5*$G$2)/SUM($E$2:$G$2) -> 1.5384615 | E5: =+POWER(5,RANDBETWEEN(1,2)-1) -> 1 | F5: =+POWER(5,RANDBETWEEN(1,2)-1) -> 1 | G5: =2*RANDBETWEEN(1,3)-1 -> 1
B6: S3 | C6: =+RANDBETWEEN(40000,45000) -> 41584 | D6: =+(E6*$E$2*F6*$F$2+G6*$G$2)/SUM($E$2:$G$2) -> 6.1538462 | E6: =+POWER(5,RANDBETWEEN(1,2)-1) -> 1 | F6: =+POWER(5,RANDBETWEEN(1,2)-1) -> 5 | G6: =2*RANDBETWEEN(1,3)-1 -> 1
B7: S4 | C7: =+RANDBETWEEN(40000,45000) -> 40633 | D7: =+(E7*$E$2*F7*$F$2+G7*$G$2)/SUM($E$2:$G$2) -> 1.5384615 | E7: =+POWER(5,RANDBETWEEN(1,2)-1) -> 1 | F7: =+POWER(5,RANDBETWEEN(1,2)-1) -> 1 | G7: =2*RANDBETWEEN(1,3)-1 -> 1
B8: S5 | C8: =+RANDBETWEEN(40000,45000) -> 41104 | D8: =+(E8*$E$2*F8*$F$2+G8*$G$2)/SUM($E$2:$G$2) -> 1.5384615 | E8: =+POWER(5,RANDBETWEEN(1,2)-1) -> 1 | F8: =+POWER(5,RANDBETWEEN(1,2)-1) -> 1 | G8: =2*RANDBETWEEN(1,3)-1 -> 1
B9: S6 | C9: =+RANDBETWEEN(40000,45000) -> 42282 | D9: =+(E9*$E$2*F9*$F$2+G9*$G$2)/SUM($E$2:$G$2) -> 29.230769 | E9: =+POWER(5,RANDBETWEEN(1,2)-1) -> 5 | F9: =+POWER(5,RANDBETWEEN(1,2)-1) -> 5 | G9: =2*RANDBETWEEN(1,3)-1 -> 1
B10: S7 | C10: =+RANDBETWEEN(40000,45000) -> 41388 | D10: =+(E10*$E$2*F10*$F$2+G10*$G$2)/SUM($E$2:$G$2) -> 7.6923077 | E10: =+POWER(5,RANDBETWEEN(1,2)-1) -> 1 | F10: =+POWER(5,RANDBETWEEN(1,2)-1) -> 5 | G10: =2*RANDBETWEEN(1,3)-1 -> 5
B11: S8 | C11: =+RANDBETWEEN(40000,45000) -> 44809 | D11: =+(E11*$E$2*F11*$F$2+G11*$G$2)/SUM($E$2:$G$2) -> 6.1538462 | E11: =+POWER(5,RANDBETWEEN(1,2)-1) -> 5 | F11: =+POWER(5,RANDBETWEEN(1,2)-1) -> 1 | G11: =2*RANDBETWEEN(1,3)-1 -> 1
B12: S9 | C12: =+RANDBETWEEN(40000,45000) -> 43644 | D12: =+(E12*$E$2*F12*$F$2+G12*$G$2)/SUM($E$2:$G$2) -> 30.769231 | E12: =+POWER(5,RANDBETWEEN(1,2)-1) -> 5 | F12: =+POWER(5,RANDBETWEEN(1,2)-1) -> 5 | G12: =2*RANDBETWEEN(1,3)-1 -> 5
B13: S10 | C13: =+RANDBETWEEN(40000,45000) -> 44081 | D13: =+(E13*$E$2*F13*$F$2+G13*$G$2)/SUM($E$2:$G$2) -> 2.3076923 | E13: =+POWER(5,RANDBETWEEN(1,2)-1) -> 1 | F13: =+POWER(5,RANDBETWEEN(1,2)-1) -> 1 | G13: =2*RANDBETWEEN(1,3)-1 -> 3

Sheet HINUC
D2: 2 | E2: 3 | F2: 5 | G2: 3
B3: SERIE | C3: FECHA | D3: HINUC | E3: P_VEX | F3: P_IEX | G3: P_RNUC
B4: S1 | C4: =+RANDBETWEEN(40000,45000) -> 44129 | D4: =+(E4*$E$2*F4*$F$2+G4*$G$2)/SUM($E$2:$G$2) -> 1.6363636 | E4: =+RANDBETWEEN(1,5) -> 1 | F4: =+POWER(5,RANDBETWEEN(1,2)-1) -> 1 | G4: =+POWER(5,RANDBETWEEN(1,2)-1) -> 1
B5: S2 | C5: =+RANDBETWEEN(40000,45000) -> 41824 | D5: =+(E5*$E$2*F5*$F$2+G5*$G$2)/SUM($E$2:$G$2) -> 7.0909091 | E5: =+RANDBETWEEN(1,5) -> 1 | F5: =+POWER(5,RANDBETWEEN(1,2)-1) -> 5 | G5: =+POWER(5,RANDBETWEEN(1,2)-1) -> 1
B6: S3 | C6: =+RANDBETWEEN(40000,45000) -> 41993 | D6: =+(E6*$E$2*F6*$F$2+G6*$G$2)/SUM($E$2:$G$2) -> 6.8181818 | E6: =+RANDBETWEEN(1,5) -> 4 | F6: =+POWER(5,RANDBETWEEN(1,2)-1) -> 1 | G6: =+POWER(5,RANDBETWEEN(1,2)-1) -> 5
B7: S4 | C7: =+RANDBETWEEN(40000,45000) -> 42841 | D7: =+(E7*$E$2*F7*$F$2+G7*$G$2)/SUM($E$2:$G$2) -> 27.545455 | E7: =+RANDBETWEEN(1,5) -> 4 | F7: =+POWER(5,RANDBETWEEN(1,2)-1) -> 5 | G7: =+POWER(5,RANDBETWEEN(1,2)-1) -> 1
B8: S5 | C8: =+RANDBETWEEN(40000,45000) -> 44878 | D8: =+(E8*$E$2*F8*$F$2+G8*$G$2)/SUM($E$2:$G$2) -> 3 | E8: =+RANDBETWEEN(1,5) -> 2 | F8: =+POWER(5,RANDBETWEEN(1,2)-1) -> 1 | G8: =+POWER(5,RANDBETWEEN(1,2)-1) -> 1
B9: S6 | C9: =+RANDBETWEEN(40000,45000) -> 40967 | D9: =+(E9*$E$2*F9*$F$2+G9*$G$2)/SUM($E$2:$G$2) -> 5.4545455 | E9: =+RANDBETWEEN(1,5) -> 3 | F9: =+POWER(5,RANDBETWEEN(1,2)-1) -> 1 | G9: =+POWER(5,RANDBETWEEN(1,2)-1) -> 5
B10: S7 | C10: =+RANDBETWEEN(40000,45000) -> 42724 | D10: =+(E10*$E$2*F10*$F$2+G10*$G$2)/SUM($E$2:$G$2) -> 15 | E10: =+RANDBETWEEN(1,5) -> 2 | F10: =+POWER(5,RANDBETWEEN(1,2)-1) -> 5 | G10: =+POWER(5,RANDBETWEEN(1,2)-1) -> 5
B11: S8 | C11: =+RANDBETWEEN(40000,45000) -> 44961 | D11: =+(E11*$E$2*F11*$F$2+G11*$G$2)/SUM($E$2:$G$2) -> 13.909091 | E11: =+RANDBETWEEN(1,5) -> 2 | F11: =+POWER(5,RANDBETWEEN(1,2)-1) -> 5 | G11: =+POWER(5,RANDBETWEEN(1,2)-1) -> 1
B12: S9 | C12: =+RANDBETWEEN(40000,45000) -> 43742 | D12: =+(E12*$E$2*F12*$F$2+G12*$G$2)/SUM($E$2:$G$2) -> 6.8181818 | E12: =+RANDBETWEEN(1,5) -> 4 | F12: =+POWER(5,RANDBETWEEN(1,2)-1) -> 1 | G12: =+POWER(5,RANDBETWEEN(1,2)-1) -> 5
B13: S10 | C13: =+RANDBETWEEN(40000,45000) -> 41720 | D13: =+(E13*$E$2*F13*$F$2+G13*$G$2)/SUM($E$2:$G$2) -> 6.8181818 | E13: =+RANDBETWEEN(1,5) -> 4 | F13: =+POWER(5,RANDBETWEEN(1,2)-1) -> 1 | G13: =+POWER(5,RANDBETWEEN(1,2)-1) -> 5

Sheet HIOLTC
D2: 1 | E2: 5 | F2: 3
B3: SERIE | C3: FECHA | D3: HIOLTC | E3: P_RD | F3: P_H2O
B4: S1 | C4: =+RANDBETWEEN(40000,45000) -> 40116 | D4: =+(E4*$E$2*F4*$F$2)/SUM($E$2:$F$2) -> 46.875 | E4: =+POWER(5,RANDBETWEEN(1,2)-1) -> 5 | F4: =+POWER(5,RANDBETWEEN(1,2)-1) -> 5
B5: S2 | C5: =+RANDBETWEEN(40000,45000) -> 40401 | D5: =+(E5*$E$2*F5*$F$2)/SUM($E$2:$F$2) -> 9.375 | E5: =+POWER(5,RANDBETWEEN(1,2)-1) -> 1 | F5: =+POWER(5,RANDBETWEEN(1,2)-1) -> 5
B6: S3 | C6: =+RANDBETWEEN(40000,45000) -> 40341 | D6: =+(E6*$E$2*F6*$F$2)/SUM($E$2:$F$2) -> 1.875 | E6: =+POWER(5,RANDBETWEEN(1,2)-1) -> 1 | F6: =+POWER(5,RANDBETWEEN(1,2)-1) -> 1
B7: S4 | C7: =+RANDBETWEEN(40000,45000) -> 41871 | D7: =+(E7*$E$2*F7*$F$2)/SUM($E$2:$F$2) -> 1.875 | E7: =+POWER(5,RANDBETWEEN(1,2)-1) -> 1 | F7: =+POWER(5,RANDBETWEEN(1,2)-1) -> 1
B8: S5 | C8: =+RANDBETWEEN(40000,45000) -> 42266 | D8: =+(E8*$E$2*F8*$F$2)/SUM($E$2:$F$2) -> 9.375 | E8: =+POWER(5,RANDBETWEEN(1,2)-1) -> 1 | F8: =+POWER(5,RANDBETWEEN(1,2)-1) -> 5
B9: S6 | C9: =+RANDBETWEEN(40000,45000) -> 43367 | D9: =+(E9*$E$2*F9*$F$2)/SUM($E$2:$F$2) -> 9.375 | E9: =+POWER(5,RANDBETWEEN(1,2)-1) -> 5 | F9: =+POWER(5,RANDBETWEEN(1,2)-1) -> 1
B10: S7 | C10: =+RANDBETWEEN(40000,45000) -> 40560 | D10: =+(E10*$E$2*F10*$F$2)/SUM($E$2:$F$2) -> 1.875 | E10: =+POWER(5,RANDBETWEEN(1,2)-1) -> 1 | F10: =+POWER(5,RANDBETWEEN(1,2)-1) -> 1
B11: S8 | C11: =+RANDBETWEEN(40000,45000) -> 41960 | D11: =+(E11*$E$2*F11*$F$2)/SUM($E$2:$F$2) -> 1.875 | E11: =+POWER(5,RANDBETWEEN(1,2)-1) -> 1 | F11: =+POWER(5,RANDBETWEEN(1,2)-1) -> 1
B12: S9 | C12: =+RANDBETWEEN(40000,45000) -> 43487 | D12: =+(E12*$E$2*F12*$F$2)/SUM($E$2:$F$2) -> 9.375 | E12: =+POWER(5,RANDBETWEEN(1,2)-1) -> 1 | F12: =+POWER(5,RANDBETWEEN(1,2)-1) -> 5
B13: S10 | C13: =+RANDBETWEEN(40000,45000) -> 41861 | D13: =+(E13*$E$2*F13*$F$2)/SUM($E$2:$F$2) -> 1.875 | E13: =+POWER(5,RANDBETWEEN(1,2)-1) -> 1 | F13: =+POWER(5,RANDBETWEEN(1,2)-1) -> 1

Sheet HIBUS
D2: 1 | E2: 4 | F2: 2 | G2: 5 | H2: 3 | I2: 3
B3: SERIE | C3: FECHA | D3: HIBUS | E3: P_FPC1 | F3: P_FPC2 | G3: P_C1 | H3: P_C2 | I3: P_CC
B4: S1 | C4: =+RANDBETWEEN(40000,45000) -> 41120 | D4: =+(E4*$E$2*F4*$F$2+G4*$G$2+H4*$H$2+I4*$I$2)/SUM($E$2:$I$2) -> 4.8823529 | E4: =2*RANDBETWEEN(1,3)-1 -> 5 | F4: =+POWER(5,RANDBETWEEN(1,2)-1) -> 1 | G4: =2*RANDBETWEEN(1,3)-1 -> 5 | H4: =+POWER(5,RANDBETWEEN(1,2)-1) -> 5 | I4: =+POWER(5,RANDBETWEEN(1,2)-1) -> 1
B5: S2 | C5: =+RANDBETWEEN(40000,45000) -> 43753 | D5: =+(E5*$E$2*F5*$F$2+G5*$G$2+H5*$H$2+I5*$I$2)/SUM($E$2:$I$2) -> 2.6470588 | E5: =2*RANDBETWEEN(1,3)-1 -> 3 | F5: =+POWER(5,RANDBETWEEN(1,2)-1) -> 1 | G5: =2*RANDBETWEEN(1,3)-1 -> 3 | H5: =+POWER(5,RANDBETWEEN(1,2)-1) -> 1 | I5: =+POWER(5,RANDBETWEEN(1,2)-1) -> 1
B6: S3 | C6: =+RANDBETWEEN(40000,45000) -> 42149 | D6: =+(E6*$E$2*F6*$F$2+G6*$G$2+H6*$H$2+I6*$I$2)/SUM($E$2:$I$2) -> 4.6470588 | E6: =2*RANDBETWEEN(1,3)-1 -> 3 | F6: =+POWER(5,RANDBETWEEN(1,2)-1) -> 1 | G6: =2*RANDBETWEEN(1,3)-1 -> 5 | H6: =+POWER(5,RANDBETWEEN(1,2)-1) -> 5 | I6: =+POWER(5,RANDBETWEEN(1,2)-1) -> 5
B7: S4 | C7: =+RANDBETWEEN(40000,45000) -> 44079 | D7: =+(E7*$E$2*F7*$F$2+G7*$G$2+H7*$H$2+I7*$I$2)/SUM($E$2:$I$2) -> 8.2941176 | E7: =2*RANDBETWEEN(1,3)-1 -> 3 | F7: =+POWER(5,RANDBETWEEN(1,2)-1) -> 5 | G7: =2*RANDBETWEEN(1,3)-1 -> 3 | H7: =+POWER(5,RANDBETWEEN(1,2)-1) -> 1 | I7: =+POWER(5,RANDBETWEEN(1,2)-1) -> 1
B8: S5 | C8: =+RANDBETWEEN(40000,45000) -> 43388 | D8: =+(E8*$E$2*F8*$F$2+G8*$G$2+H8*$H$2+I8*$I$2)/SUM($E$2:$I$2) -> 3.3529412 | E8: =2*RANDBETWEEN(1,3)-1 -> 3 | F8: =+POWER(5,RANDBETWEEN(1,2)-1) -> 1 | G8: =2*RANDBETWEEN(1,3)-1 -> 3 | H8: =+POWER(5,RANDBETWEEN(1,2)-1) -> 5 | I8: =+POWER(5,RANDBETWEEN(1,2)-1) -> 1
B9: S6 | C9: =+RANDBETWEEN(40000,45000) -> 43080 | D9: =+(E9*$E$2*F9*$F$2+G9*$G$2+H9*$H$2+I9*$I$2)/SUM($E$2:$I$2) -> 1.8235294 | E9: =2*RANDBETWEEN(1,3)-1 -> 1 | F9: =+POWER(5,RANDBETWEEN(1,2)-1) -> 1 | G9: =2*RANDBETWEEN(1,3)-1 -> 1 | H9: =+POWER(5,RANDBETWEEN(1,2)-1) -> 5 | I9: =+POWER(5,RANDBETWEEN(1,2)-1) -> 1
B10: S7 | C10: =+RANDBETWEEN(40000,45000) -> 44237 | D10: =+(E10*$E$2*F10*$F$2+G10*$G$2+H10*$H$2+I10*$I$2)/SUM($E$2:$I$2) -> 3.3529412 | E10: =2*RANDBETWEEN(1,3)-1 -> 3 | F10: =+POWER(5,RANDBETWEEN(1,2)-1) -> 1 | G10: =2*RANDBETWEEN(1,3)-1 -> 3 | H10: =+POWER(5,RANDBETWEEN(1,2)-1) -> 5 | I10: =+POWER(5,RANDBETWEEN(1,2)-1) -> 1
B11: S8 | C11: =+RANDBETWEEN(40000,45000) -> 40691 | D11: =+(E11*$E$2*F11*$F$2+G11*$G$2+H11*$H$2+I11*$I$2)/SUM($E$2:$I$2) -> 1.1176471 | E11: =2*RANDBETWEEN(1,3)-1 -> 1 | F11: =+POWER(5,RANDBETWEEN(1,2)-1) -> 1 | G11: =2*RANDBETWEEN(1,3)-1 -> 1 | H11: =+POWER(5,RANDBETWEEN(1,2)-1) -> 1 | I11: =+POWER(5,RANDBETWEEN(1,2)-1) -> 1
B12: S9 | C12: =+RANDBETWEEN(40000,45000) -> 43885 | D12: =+(E12*$E$2*F12*$F$2+G12*$G$2+H12*$H$2+I12*$I$2)/SUM($E$2:$I$2) -> 4.8823529 | E12: =2*RANDBETWEEN(1,3)-1 -> 5 | F12: =+POWER(5,RANDBETWEEN(1,2)-1) -> 1 | G12: =2*RANDBETWEEN(1,3)-1 -> 5 | H12: =+POWER(5,RANDBETWEEN(1,2)-1) -> 1 | I12: =+POWER(5,RANDBETWEEN(1,2)-1) -> 5
B13: S10 | C13: =+RANDBETWEEN(40000,45000) -> 44064 | D13: =+(E13*$E$2*F13*$F$2+G13*$G$2+H13*$H$2+I13*$I$2)/SUM($E$2:$I$2) -> 2.5294118 | E13: =2*RANDBETWEEN(1,3)-1 -> 1 | F13: =+POWER(5,RANDBETWEEN(1,2)-1) -> 1 | G13: =2*RANDBETWEEN(1,3)-1 -> 1 | H13: =+POWER(5,RANDBETWEEN(1,2)-1) -> 5 | I13: =+POWER(5,RANDBETWEEN(1,2)-1) -> 5
